{"name": "test_safe_delete_file_exception_logged", "status": "passed", "description": "Unit test the helper to ensure it logs (doesn't raise) on deletion failure.", "start": 1755785114246, "stop": 1755785114249, "uuid": "cccb9708-00e4-4681-a089-31496da7ceb1", "historyId": "d8e2433d1c2da0f28504a4b60b8eab04", "testCaseId": "d8e2433d1c2da0f28504a4b60b8eab04", "fullName": "tests.test_delete.TestDeletePredictionEndpoint#test_safe_delete_file_exception_logged", "labels": [{"name": "parentSuite", "value": "tests"}, {"name": "suite", "value": "test_delete"}, {"name": "subSuite", "value": "TestDeletePredictionEndpoint"}, {"name": "host", "value": "LAPTOP-J12RM8I3"}, {"name": "thread", "value": "373292-MainThread"}, {"name": "framework", "value": "pytest"}, {"name": "language", "value": "cpython3"}, {"name": "package", "value": "tests.test_delete"}], "titlePath": ["tests", "test_delete.py", "TestDeletePredictionEndpoint"]}